<?xml version="1.0" ?>
<!-- @file dustbuster.urdf
@brief This file contains the description of the DustBuster robot model.

@details This file includes the robot's links, joints, materials, sensors, and other properties used in the simulation, nav2 and slam.
-->
<robot name="dustbuster">
  <!-- Specify some standard inertial calculations https://en.wikipedia.org/wiki/List_of_moments_of_inertia -->
  <!-- These make use of xacro's mathematical functionality -->
  <material name="white">
    <color rgba="1 1 1 1"/>
  </material>

  <material name="grey">
    <color rgba="0.212 0.212 0.212 1"/>
  </material>

  <material name="steel">
    <color rgba="0.5 0.5 0.5 1"/>
  </material>

  <material name="black">
    <color rgba="0 0 0 1"/>
  </material>

  <!-- BASE LINK -->
  <link name="base_link">

  </link>
  <!-- BASE_FOOTPRINT LINK -->
  <joint name="base_footprint_joint" type="fixed">
    <parent link="base_link"/>
    <child link="base_footprint"/>
    <origin rpy="0 0 0" xyz="0 0 0"/>
  </joint>
  <link name="base_footprint">
    </link>
  <!-- CHASSIS LINK -->
  <joint name="chassis_joint" type="fixed">
    <parent link="base_link"/>
    <child link="chassis"/>
    <origin xyz="0 0 0"/>
  </joint>
  
  <link name="chassis">
    <inertial>
      <mass value="22.5"/>
      <inertia ixx="0.413495" ixy="0" ixz="0" iyy="0.5608725" iyz="0.00" izz="0.8594225" />
      <origin rpy="0 -0 0" xyz="0 0 0"/> <!-- x: 0 -->
    </inertial>
    <visual name="visual">
      <origin rpy="0 -0 0" xyz="0 0 0"/> <!-- x: 0 -->

    <!-- Import mesh from package doesn't work -->
    <!-- https://answers.ros.org/question/401649/gazebo-does-not-spawn-mesh/-->
    <geometry>
      <mesh filename="file:///home/onur/Desktop/DustBusterAI-Software/dustbuster_ws/src/dustbuster_launch/dustbuster_launch/description/mesh/chassis.stl"/>
    </geometry>
      <material name="steel"/>
    </visual>

    <!-- Import mesh from package doesn't work -->
    <!-- https://answers.ros.org/question/401649/gazebo-does-not-spawn-mesh/-->
    <collision name="collision">
      <origin rpy="0 -0 0" xyz="0 0 0"/>
      <geometry>
        <mesh filename="file:///home/onur/Desktop/DustBusterAI-Software/dustbuster_ws/src/dustbuster_launch/dustbuster_launch/description/mesh/chassis.stl"/>
      </geometry>
    </collision>
  </link>


  <!-- LEFT WHEEL LINK -->
  <joint name="left_wheel_joint" type="continuous">
    <parent link="base_link"/>
    <child link="left_wheel"/>
    <origin rpy="-1.5707963267948966 0 0" xyz="0 0.2935 0"/> <!-- y: 0.2935 -->
    <axis xyz="0 0 1"/>
  </joint>

  <link name="left_wheel">
    <visual>
      <geometry>
        <cylinder length="0.05" radius="0.1225"/>
      </geometry>
    </visual>
    <collision>
      <geometry>
        <cylinder length="0.05" radius="0.1225"/>
      </geometry>
    </collision>
    <inertial>
      <origin rpy="0 0 0" xyz="0 0 0"/>
      <mass value="0.5"/>
			<inertia ixx="0.0019799479" ixy="0.0" ixz="0.0" iyy="0.00375234375" iyz="0.0" izz="0.0019799479"/>
    </inertial>
  </link>

  <gazebo reference="left_wheel">
    <material>Gazebo/Grey</material>
    <surface>
      <friction>
        <ode>
          <mu>0.8</mu>
          <mu2>0.7</mu2>
        </ode>
      </friction>
    </surface>
  </gazebo>

  <!-- RIGHT WHEEL LINK -->
  <joint name="right_wheel_joint" type="continuous">
    <parent link="base_link"/>
    <child link="right_wheel"/>
    <origin rpy="1.5707963267948966 0 0" xyz="0 -0.2935 0"/> <!-- y: -0.2935 -->
    <axis xyz="0 0 -1"/>
  </joint>

  <link name="right_wheel">
    <visual>
      <geometry>
        <cylinder length="0.05" radius="0.1225"/>
      </geometry>
    </visual>
    <collision>
      <geometry>
        <cylinder length="0.05" radius="0.1225"/>
      </geometry>
    </collision>
    <inertial>
      <origin rpy="0 0 0" xyz="0 0 0"/>
      <mass value="0.5"/>
			<inertia ixx="0.0019799479" ixy="0.0" ixz="0.0" iyy="0.00375234375" iyz="0.0" izz="0.0019799479"/>
    </inertial>
  </link>

  <gazebo reference="right_wheel">
    <material>Gazebo/Grey</material>
    <surface>
      <friction>
        <ode>
          <mu>0.8</mu>
          <mu2>0.7</mu2>
        </ode>
      </friction>
    </surface>
  </gazebo>

  <!-- CASTER WHEEL MOUNT LINK -->
  <link name="caster_wheel_mount">
    <visual>
      <geometry>
        <box size="0.025 0.025 0.06"/>
      </geometry>
      <material name="grey"/>
    </visual>
    <collision>
      <geometry>
        <box size="0.025 0.025 0.06"/>
      </geometry>
    </collision>
    <inertial>
      <origin rpy="0 0 0" xyz="0 0 0"/>
      <mass value="0.1"/> 
      <inertia ixx="0.00003520833" ixy="0.0" ixz="0.0" iyy="0.00003520833" iyz="0.0" izz="0.0000104166667"/>
    </inertial>
  </link>

  <joint name="caster_wheel_mount_joint" type="revolute">
    <parent link="chassis"/>
    <child link="caster_wheel_mount"/>
    <origin rpy="0 0 0" xyz="0.35 0 -0.0625"/> <!-- x: 0.35 -->
    <axis xyz="0 0 1"/>
    <limit lower="-100000000000000000000" upper="100000000000000000000" effort="1.0" velocity="2.0"/>
  </joint>

  <!-- CASTER WHEEL LINK -->
  <link name="caster_wheel">
    <visual>
      <geometry>	
        <cylinder length="0.02" radius="0.035"/>
      </geometry>
      <material name="grey"/>
    </visual>
    <collision>
      <geometry>
        <cylinder length="0.02" radius="0.035"/>
      </geometry>
    </collision>
    <inertial>
      <origin rpy="0 0 0" xyz="0 0 0"/>
      <mass value="0.1"/>
			<inertia ixx="0.000033958333" ixy="0.0" ixz="0.0" iyy="0.00006125" iyz="0.0" izz="0.000033958333"/>
    </inertial>
  </link>

  <gazebo reference="caster_wheel">
    <material>Gazebo/Grey</material>
    <surface>
      <friction>
        <ode>
          <mu>0.8</mu>
          <mu2>0.7</mu2>
        </ode>
      </friction>
    </surface>
  </gazebo>

  <!-- CASTER WHEEL JOINT -->
  <joint name="caster_wheel_joint" type="revolute">
    <parent link="caster_wheel_mount"/>
    <child link="caster_wheel"/>
    <origin rpy="1.5707963267948966 0 0" xyz="0 0 -0.025"/> <!-- x: 0.35 -->
    <axis xyz="0 0 1"/>
    <limit lower="-100000000000000000000" upper="100000000000000000000" effort="1.0" velocity="2.0"/>
  </joint>

  <joint name="laser_joint" type="fixed">
    <parent link="chassis"/>
    <child link="laser_frame"/>
    <origin rpy="0 0 0" xyz="0.122 0 0.25"/> <!-- x: 0.122 -->
  </joint>
  <link name="laser_frame">
    <visual>
      <geometry>
        <cylinder length="0.04" radius="0.05"/>
      </geometry>
      <material name="black"/>
    </visual>
    <visual>
      <origin xyz="0 0 -0.05"/>
      <geometry>
        <cylinder length="0.1" radius="0.01"/>
      </geometry>
      <material name="black"/>
    </visual>
    <collision>
      <geometry>
        <cylinder length="0.04" radius="0.05"/>
      </geometry>
    </collision>
    <inertial>
      <origin rpy="0 0 0" xyz="0 0 0"/>
      <mass value="0.1"/>
      <inertia ixx="7.583333333333335e-05" ixy="0.0" ixz="0.0" iyy="7.583333333333335e-05" iyz="0.0" izz="0.00012500000000000003"/>
    </inertial>
  </link>

  <gazebo reference="laser_frame">
    <material>Gazebo/Black</material>
    <sensor name="laser" type="ray">
      <pose> 0 0 0 0 0 0 </pose>
      <visualize>true</visualize>
      <update_rate>10</update_rate> <!--Hokuyo-URG04LX-UG01-->
      <ray>
        <scan>
          <horizontal>
            <samples>683</samples>  <!--Hokuyo-URG04LX-UG01-->
            <min_angle>-2.08621</min_angle>
            <max_angle>2.08621</max_angle>
          </horizontal>
        </scan>
        <range> <!--Hokuyo-URG04LX-UG01-->
          <min>0.2</min>
          <max>5.6</max>
        </range>
      </ray>
      <plugin filename="libgazebo_ros_ray_sensor.so" name="laser_controller">
        <ros>
          <argument>~/out:=scan</argument>
        </ros>
        <output_type>sensor_msgs/LaserScan</output_type>
        <frame_name>laser_frame</frame_name>
      </plugin>
    </sensor>
  </gazebo>
  <joint name="camera_joint" type="fixed">
    <parent link="chassis"/>
    <child link="camera_link"/>
    <origin rpy="0 0 0" xyz="0.276 0 0.181"/> <!-- x: 0.276 -->
  </joint>

  <link name="camera_link">
    <visual>
      <geometry>
        <box size="0.010 0.03 0.03"/>
      </geometry>
      <material name="black"/>
    </visual>
    <visual>
      <origin xyz="0 0 -0.05"/>
      <geometry>
        <cylinder length="0.1" radius="0.002"/>
      </geometry>
      <material name="black"/>
    </visual>
    <inertial> <!--inertial parameters of camera_link is used to balance the center of mass, they do not actually belong to camera-->
      <mass value="3.1"/> 
      <origin xyz="0 0 0"/>
      <inertia ixx="0.01" ixy="0" ixz="0" iyy="0.01" iyz="0" izz="0.01"/>
    </inertial>
</link>

  <joint name="camera_optical_joint" type="fixed">
    <parent link="camera_link"/>
    <child link="camera_link_optical"/>
    <origin rpy="-1.5707963267948966 0 -1.5707963267948966" xyz="0.5 0 0"/>
  </joint>
	
  <link name="camera_link_optical"/>
  <gazebo reference="camera_link">
    <material>Gazebo/Black</material>
    <sensor name="camera" type="camera">
      <pose> 0 0 0 0 0 0 </pose>
      <visualize>true</visualize>
      <update_rate>10</update_rate>
      <camera>
        <horizontal_fov>1.089</horizontal_fov>
        <image>
          <format>R8G8B8</format>
          <width>640</width>
          <height>480</height>
        </image>
        <clip>
          <near>0.05</near>
          <far>8.0</far>
        </clip>
      </camera>
      <plugin filename="libgazebo_ros_camera.so" name="camera_controller">
        <frame_name>camera_link_optical</frame_name>
      </plugin>
    </sensor>
  </gazebo>

  <gazebo>
    <plugin name="diff_drive" filename="libgazebo_ros_diff_drive.so">
      <!-- Wheel Information -->
      <left_joint>left_wheel_joint</left_joint>
      <right_joint>right_wheel_joint</right_joint>
      <wheel_separation>0.587</wheel_separation>
      <wheel_diameter>0.245</wheel_diameter>

      <!-- Limits -->
      <max_wheel_torque>200</max_wheel_torque>
      <max_wheel_acceleration>10.0</max_wheel_acceleration>

      <!-- Output -->
      <odometry_frame>odom</odometry_frame>
      <robot_base_frame>base_link</robot_base_frame>

      <publish_odom>true</publish_odom>
      <publish_odom_tf>true</publish_odom_tf>
      <publish_wheel_tf>true</publish_wheel_tf>

    </plugin>
	</gazebo>

	<link name="imu_link">
		<inertial>
			<origin rpy="0 0 0" xyz="0 0 0"/>
			<mass value="0.01"/>
			<inertia ixx="0.00001" ixy="0" ixz="0" iyy="0.00001" iyz="0" izz="0.00001"/>
		</inertial>
		<visual>
			<origin rpy="0 0 0" xyz="0 0 0"/>
			<geometry>
				<box size="0.01 0.01 0.01"/>
			</geometry>
			<material name="black"/>
		</visual>
	</link>

	<joint name="imu_joint" type="fixed">
		<parent link="base_link"/>
		<child link="imu_link"/>
		<origin rpy="0 0 0" xyz="0 0 0"/> 
	</joint>

	<gazebo reference="imu_link">
		<sensor name="imu_sensor" type="imu">
			<always_on>true</always_on>
			<update_rate>200</update_rate>
			<plugin name="gazebo_ros_imu_controller" filename="libgazebo_ros_imu_sensor.so">
				<ros>
					<argument>~/out:=imu</argument>
				</ros>
				<body_name>imu_link</body_name>
				<topicName>imu/data</topicName>
				<frameId>imu_link</frameId>
				<xyzOffsets>0 0 0</xyzOffsets>
				<rpyOffsets>0 0 0</rpyOffsets>
				<gaussianNoise>0.0</gaussianNoise>
				<biasTopic>~/imu/bias</biasTopic>
			</plugin>
		</sensor>
	</gazebo>

</robot>

