<?xml version="1.0" ?>
<!-- =================================================================================== -->
<!-- |    This document was autogenerated by xacro from robot.urdf.xacro               | -->
<!-- |    EDITING THIS FILE BY HAND IS NOT RECOMMENDED                                 | -->
<!-- =================================================================================== -->
<robot name="robot">
  <!-- Specify some standard inertial calculations https://en.wikipedia.org/wiki/List_of_moments_of_inertia -->
  <!-- These make use of xacro's mathematical functionality -->
  <material name="white">
    <color rgba="1 1 1 1"/>
  </material>
  <material name="orange">
    <color rgba="1 0.3 0.1 1"/>
  </material>
  <material name="blue">
    <color rgba="0.2 0.2 1 1"/>
  </material>
  <material name="black">
    <color rgba="0 0 0 1"/>
  </material>
  <material name="red">
    <color rgba="1 0 0 1"/>
  </material>
  <!-- BASE LINK -->
  <link name="base_link">

  </link>
  <!-- BASE_FOOTPRINT LINK -->
  <joint name="base_footprint_joint" type="fixed">
    <parent link="base_link"/>
    <child link="base_footprint"/>
    <origin rpy="0 0 0" xyz="0 0 0"/>
  </joint>
  <link name="base_footprint">
    </link>
  <!-- CHASSIS LINK -->
  <joint name="chassis_joint" type="fixed">
    <parent link="base_link"/>
    <child link="chassis"/>
    <origin xyz="-0.226 0 -0.01"/>
  </joint>
  
  <link name="chassis">
    <inertial>
      <mass value="20"/>
      <inertia ixx="1.26558" ixy="0" ixz="0" iyy="1.26558" iyz="0" izz="2.5"/>
      <origin rpy="0 -0 0" xyz="0 0 0"/>
    </inertial>
    <visual name="visual">
      <origin rpy="0 -0 0" xyz="0 0 0"/>
      <geometry>
        <cylinder length="0.0966706" radius="0.5"/>
      </geometry>
      <material name="black"/>
    </visual>
    <collision name="collision">
      <origin rpy="0 -0 0" xyz="0 0 0"/>
      <geometry>
        <cylinder length="0.096671" radius="0.5"/>
      </geometry>
    </collision>
  </link>

  <gazebo reference="chassis">
    <material>Gazebo/Orange</material>
  </gazebo>
  <!-- LEFT WHEEL LINK -->
  <joint name="left_wheel_joint" type="continuous">
    <parent link="base_link"/>
    <child link="left_wheel"/>
    <origin rpy="-1.5707963267948966 0 0" xyz="-0.25 0.58 0"/>
    <axis xyz="0 0 1"/>
  </joint>
  <link name="left_wheel">
    <visual>
      <geometry>
        <cylinder length="0.071441" radius="0.216015"/>
      </geometry>
      <material name="blue"/>
    </visual>
    <collision>
      <geometry>
        <cylinder length="0.071441" radius="0.216015"/>
      </geometry>
    </collision>
    <inertial>
      <origin rpy="0 0 0" xyz="0 0 0"/>
      <mass value="1.5"/>
      <inertia ixx="1.642916666666667e-05" ixy="0.0" ixz="0.0" iyy="1.642916666666667e-05" iyz="0.0" izz="2.7225000000000004e-05"/>
    </inertial>
  </link>
  <gazebo reference="left_wheel">
    <material>Gazebo/Blue</material>
  </gazebo>
  <!-- RIGHT WHEEL LINK -->
  <joint name="right_wheel_joint" type="continuous">
    <parent link="base_link"/>
    <child link="right_wheel"/>
    <origin rpy="1.5707963267948966 0 0" xyz="-0.25 -0.58 0"/>
    <axis xyz="0 0 -1"/>
  </joint>
  <link name="right_wheel">
    <visual>
      <geometry>
        <cylinder length="0.071441" radius="0.216015"/>
      </geometry>
      <material name="blue"/>
    </visual>
    <collision>
      <geometry>
        <cylinder length="0.071441" radius="0.216015"/>
      </geometry>
    </collision>
    <inertial>
      <origin rpy="0 0 0" xyz="0 0 0"/>
      <mass value="1.5"/>
      <inertia ixx="1.642916666666667e-05" ixy="0.0" ixz="0.0" iyy="1.642916666666667e-05" iyz="0.0" izz="2.7225000000000004e-05"/>
    </inertial>
  </link>
  <gazebo reference="right_wheel">
    <material>Gazebo/Blue</material>
  </gazebo>
  <!-- CASTER WHEEL LINK -->
  <link name="caster_wheel">
    <visual>
      <geometry>
        <cylinder length="0.0320289" radius="0.0601226"/>
      </geometry>
      <material name="blue"/>
    </visual>
    <collision>
      <geometry>
        <cylinder length="0.032029" radius="0.060123"/>
      </geometry>
    </collision>
    <inertial>
      <origin rpy="0 0 0" xyz="0 0 0"/>
      <mass value="0.5"/>
      <inertia ixx="1.642916666666667e-05" ixy="0.0" ixz="0.0" iyy="1.642916666666667e-05" iyz="0.0" izz="2.7225000000000004e-05"/>
    </inertial>
  </link>

  <gazebo reference="caster_wheel">
    <mu1 value="0.001"/>
    <mu2 value="0.001"/>
    <material>Gazebo/Blue</material>
  </gazebo>

  <joint name="caster_wheel_joint" type="fixed">
    <parent link="chassis"/>
    <child link="caster_wheel"/>
    <origin rpy="1.5707963267948966 0 0" xyz="0.35 0 -0.15"/>
  </joint>

  <joint name="laser_joint" type="fixed">
    <parent link="chassis"/>
    <child link="laser_frame"/>
    <origin rpy="0 0 0" xyz="0.122 0 0.25"/>
  </joint>
  <link name="laser_frame">
    <visual>
      <geometry>
        <cylinder length="0.04" radius="0.05"/>
      </geometry>
      <material name="black"/>
    </visual>
    <visual>
      <origin xyz="0 0 -0.05"/>
      <geometry>
        <cylinder length="0.1" radius="0.01"/>
      </geometry>
      <material name="black"/>
    </visual>
    <collision>
      <geometry>
        <cylinder length="0.04" radius="0.05"/>
      </geometry>
    </collision>
    <inertial>
      <origin rpy="0 0 0" xyz="0 0 0"/>
      <mass value="0.1"/>
      <inertia ixx="7.583333333333335e-05" ixy="0.0" ixz="0.0" iyy="7.583333333333335e-05" iyz="0.0" izz="0.00012500000000000003"/>
    </inertial>
  </link>
  <gazebo reference="laser_frame">
    <material>Gazebo/Black</material>
    <sensor name="laser" type="ray">
      <pose> 0 0 0 0 0 0 </pose>
      <visualize>true</visualize>
      <update_rate>10</update_rate>
      <ray>
        <scan>
          <horizontal>
            <samples>360</samples>
            <min_angle>-2.35619449</min_angle>
            <max_angle>2.35619449</max_angle>
          </horizontal>
        </scan>
        <range>
          <min>0.3</min>
          <max>12</max>
        </range>
      </ray>
      <plugin filename="libgazebo_ros_ray_sensor.so" name="laser_controller">
        <ros>
          <argument>~/out:=scan</argument>
        </ros>
        <output_type>sensor_msgs/LaserScan</output_type>
        <frame_name>laser_frame</frame_name>
      </plugin>
    </sensor>
  </gazebo>
  <joint name="camera_joint" type="fixed">
    <parent link="chassis"/>
    <child link="camera_link"/>
    <origin rpy="0 0 0" xyz="0.276 0 0.181"/>
  </joint>
  <link name="camera_link">
    <visual>
      <geometry>
        <box size="0.010 0.03 0.03"/>
      </geometry>
      <material name="black"/>
    </visual>
    <visual>
      <origin xyz="0 0 -0.05"/>
      <geometry>
        <cylinder length="0.1" radius="0.002"/>
      </geometry>
      <material name="black"/>
    </visual>
  </link>
  <joint name="camera_optical_joint" type="fixed">
    <parent link="camera_link"/>
    <child link="camera_link_optical"/>
    <origin rpy="-1.5707963267948966 0 -1.5707963267948966" xyz="0 0 0"/>
  </joint>
  <link name="camera_link_optical"/>
  <gazebo reference="camera_link">
    <material>Gazebo/Black</material>
    <sensor name="camera" type="camera">
      <pose> 0 0 0 0 0 0 </pose>
      <visualize>true</visualize>
      <update_rate>10</update_rate>
      <camera>
        <horizontal_fov>1.089</horizontal_fov>
        <image>
          <format>R8G8B8</format>
          <width>640</width>
          <height>480</height>
        </image>
        <clip>
          <near>0.05</near>
          <far>8.0</far>
        </clip>
      </camera>
      <plugin filename="libgazebo_ros_camera.so" name="camera_controller">
        <frame_name>camera_link_optical</frame_name>
      </plugin>
    </sensor>
  </gazebo>
  <!-- <xacro:include filename="depth_camera.xacro" /> -->

  <gazebo>
    <plugin name="diff_drive" filename="libgazebo_ros_diff_drive.so">
    
      <!-- Wheel Information -->
      <left_joint>left_wheel_joint</left_joint>
      <right_joint>right_wheel_joint</right_joint>
      <wheel_separation>1.16</wheel_separation>
      <wheel_diameter>0.43203</wheel_diameter>


      <!-- Limits -->
      <max_wheel_torque>200</max_wheel_torque>
      <max_wheel_acceleration>10.0</max_wheel_acceleration>

            
      <!-- Output -->
      <odometry_frame>odom</odometry_frame>
      <robot_base_frame>base_link</robot_base_frame>

      <publish_odom>true</publish_odom>
      <publish_odom_tf>true</publish_odom_tf>
      <publish_wheel_tf>true</publish_wheel_tf>

    </plugin>
</gazebo>

</robot>
