<?xml version="1.0" ?>
<!-- =================================================================================== -->
<!-- |    This document was autogenerated by xacro from robot_draft.urdf.xacro         | -->
<!-- |    EDITING THIS FILE BY HAND IS NOT RECOMMENDED                                 | -->
<!-- =================================================================================== -->
<robot name="robot_draft">
  <link name="laser_frame">
    <pose>0 0 0 0 -0 1.57588</pose>
    <inertial>
      <origin rpy="0 -0 0" xyz="0 0 0.035003"/>
      <mass value="0.130033"/>
      <inertia ixx="2.628e-05" ixy="0" ixz="0" iyy="2.628e-05" iyz="0" izz="2.601e-05"/>
    </inertial>
    <visual name="visual">
      <origin rpy="0 -0 1.5707" xyz="0 0 0"/>
      <geometry>
        <mesh filename="file:///home/onur/Desktop/DustBusterAI-Software/dustbuster_ws/description/mesh/lidar_2d_v1.dae"/>
      </geometry>
    </visual>
    <collision name="collision_base">
      <origin rpy="0 -0 0" xyz="0 0 0.017502"/>
      <geometry>
        <box size="0.050011 0.050011 0.035003"/>
      </geometry>
    </collision>
    <collision name="collision_top">
      <origin rpy="0 -0 0" xyz="0 0 0.052505"/>
      <geometry>
        <cylinder length="0.035003" radius="0.02"/>
      </geometry>
    </collision>
  </link>
  <gazebo reference="laser_frame">
    <sensor name="laser" type="ray">
      <pose>0 0 0.052505 0 -0 0</pose>
      <ray>
        <scan>
          <horizontal>
            <samples>540</samples>
            <resolution>1</resolution>
            <min_angle>-2.3562</min_angle>
            <max_angle>2.3562</max_angle>
          </horizontal>
          <vertical>
            <samples>1</samples>
            <min_angle>0</min_angle>
            <max_angle>0</max_angle>
          </vertical>
        </scan>
        <range>
          <min>0.06</min>
          <max>5</max>
          <resolution>0.01</resolution>
        </range>
        <noise>
          <type>gaussian</type>
          <mean>0</mean>
          <stddev>0.001</stddev>
        </noise>
      </ray>
      <plugin filename="libgazebo_ros_ray_sensor.so" name="laser_controller">
        <ros>
          <argument>--ros-args --remap ~/out:=scan</argument>
        </ros>
        <output_type>sensor_msgs/LaserScan</output_type>
        <frame_name>laser_frame</frame_name>
      </plugin>
      <always_on>0</always_on>
      <update_rate>30</update_rate>
      <visualize>1</visualize>
    </sensor>
  </gazebo>
  <material name="blackfsdf">
    <color rgba="0 0 0 1"/>
  </material>
  <link name="caster_wheel">
    <inertial>
      <mass value="2"/>
      <inertia ixx="0.00197836" ixy="0" ixz="0" iyy="0.00197836" iyz="0" izz="0.00361478"/>
      <origin rpy="0 -0 0" xyz="0 0 0"/>
    </inertial>
    <visual name="visual">
      <origin rpy="0 -0 0" xyz="0 0 0"/>
      <geometry>
        <cylinder length="0.0320289" radius="0.0601226"/>
      </geometry>
      <material name="blackfsdf"/>
    </visual>
    <collision name="collision">
      <origin rpy="0 -0 0" xyz="0 0 0"/>
      <geometry>
        <cylinder length="0.032029" radius="0.060123"/>
      </geometry>
    </collision>
  </link>
  <link name="chassis">
    <inertial>
      <mass value="20"/>
      <inertia ixx="1.26558" ixy="0" ixz="0" iyy="1.26558" iyz="0" izz="2.5"/>
      <origin rpy="0 -0 0" xyz="0 0 0"/>
    </inertial>
    <visual name="visual">
      <origin rpy="0 -0 0" xyz="0 0 0"/>
      <geometry>
        <cylinder length="0.0966706" radius="0.5"/>
      </geometry>
      <material name="blackfsdf"/>
    </visual>
    <collision name="collision">
      <origin rpy="0 -0 0" xyz="0 0 0"/>
      <geometry>
        <cylinder length="0.096671" radius="0.5"/>
      </geometry>
    </collision>
  </link>
  <link name="left_wheel">
    <inertial>
      <mass value="1.5"/>
      <inertia ixx="0.0181364" ixy="0" ixz="0" iyy="0.0181364" iyz="0" izz="0.0349969"/>
      <origin rpy="0 -0 0" xyz="0 0 0"/>
    </inertial>
    <visual name="visual">
      <origin rpy="0 -0 0" xyz="0 0 0"/>
      <geometry>
        <cylinder length="0.071441" radius="0.216015"/>
      </geometry>
      <material name="blackfsdf"/>
    </visual>
    <collision name="collision">
      <origin rpy="0 -0 0" xyz="0 0 0"/>
      <geometry>
        <cylinder length="0.071441" radius="0.216015"/>
      </geometry>
    </collision>
  </link>
  <link name="right_wheel">
    <inertial>
      <mass value="1.5"/>
      <inertia ixx="0.0181364" ixy="0" ixz="0" iyy="0.0181364" iyz="0" izz="0.0349969"/>
      <origin rpy="0 -0 0" xyz="0 0 0"/>
    </inertial>
    <visual name="visual">
      <origin rpy="0 -0 0" xyz="0 0 0"/>
      <geometry>
        <cylinder length="0.071441" radius="0.216015"/>
      </geometry>
      <material name="blackfsdf"/>
    </visual>
    <collision name="collision">
      <origin rpy="0 -0 0" xyz="0 0 0"/>
      <geometry>
        <cylinder length="0.071441" radius="0.216015"/>
      </geometry>
    </collision>
  </link>
  <joint name="caster_wheel_joint" type="continuous">
    <parent link="chassis"/>
    <child link="caster_wheel"/>
    <origin rpy="-3.13946 1.57079 -3.13946" xyz="0 0.474958 -0.113119"/>
    <axis xyz="0 0 -1"/>
    <dynamics damping="0.0" friction="0.0"/>
  </joint>
  <joint name="left_wheel_joint" type="continuous">
    <parent link="chassis"/>
    <child link="left_wheel"/>
    <origin rpy="-3.13946 1.57079 -3.13946" xyz="-0.58 -0.08 0"/>
    <axis xyz="0 0 -1"/>
    <dynamics damping="0.0" friction="0.0"/>
  </joint>
  <joint name="right_wheel_joint" type="continuous">
    <parent link="chassis"/>
    <child link="right_wheel"/>
    <origin rpy="0 1.57079 0" xyz="0.58 -0.08 0"/>
    <axis xyz="0 0 -1"/>
    <dynamics damping="0.0" friction="0.0"/>
  </joint>
  <joint name="laser_joint" type="fixed">
    <parent link="chassis"/>
    <child link="laser_frame"/>
    <origin rpy="0 0 1.570796" xyz="0 0.25 0.25"/>
  </joint>
  <gazebo>
    <plugin filename="libwheel_velocity_setter.so" name="wheel_velocity_setter"/>
    
  </gazebo>
  

</robot>
